2023-01-23 23:00:10,751 - kedro.pipeline.node - ERROR - Node 'run_outlier_detection_node: run_outlier_detection([preprocessed_raw_data]) -> [processed_data]' failed with error: 
name 'fit_predict_model' is not defined
2023-01-23 23:13:15,688 - kedro.pipeline.node - ERROR - Node 'run_outlier_detection_node: run_outlier_detection([preprocessed_raw_data]) -> [processed_data]' failed with error: 
name '_fit_predict_model' is not defined
2023-01-23 23:14:34,393 - kedro.pipeline.node - ERROR - Node 'run_outlier_detection_node: run_outlier_detection([preprocessed_raw_data]) -> [processed_data]' failed with error: 
name 'fit_predict_model' is not defined
2023-01-23 23:43:05,642 - kedro.pipeline.node - ERROR - Node 'run_outlier_detection_node: run_outlier_detection([preprocessed_raw_data]) -> [processed_data]' failed with error: 
name 'fit_predict_model' is not defined
2023-01-24 00:26:05,879 - kedro.pipeline.node - ERROR - Node 'run_outlier_detection_node: run_outlier_detection([preprocessed_raw_data]) -> [processed_data]' failed with error: 
Unable to parse string "datakaveri.org/04a15c9960ffda227e9546f3f46e629e1fe4132b/rs.iudx.org.in/pune-env-aqm/3c84ae0f-dcca-fd9b-1f09-bc0f0e092b63" at position 0
2023-01-24 00:31:30,907 - kedro.pipeline.node - ERROR - Node 'run_outlier_detection_node: run_outlier_detection([preprocessed_raw_data]) -> [processed_data]' failed with error: 
Unable to parse string "datakaveri.org/04a15c9960ffda227e9546f3f46e629e1fe4132b/rs.iudx.org.in/pune-env-aqm/3c84ae0f-dcca-fd9b-1f09-bc0f0e092b63" at position 0
2023-01-24 00:40:18,106 - kedro.pipeline.node - ERROR - Node 'run_outlier_detection_node: run_outlier_detection([preprocessed_raw_data]) -> [processed_data]' failed with error: 
Unable to parse string "datakaveri.org/04a15c9960ffda227e9546f3f46e629e1fe4132b/rs.iudx.org.in/pune-env-aqm/3c84ae0f-dcca-fd9b-1f09-bc0f0e092b63" at position 0
2023-01-24 00:42:48,540 - kedro.pipeline.node - ERROR - Node 'run_outlier_detection_node: run_outlier_detection([preprocessed_raw_data]) -> [processed_data]' failed with error: 
Unable to parse string "datakaveri.org/04a15c9960ffda227e9546f3f46e629e1fe4132b/rs.iudx.org.in/pune-env-aqm/3c84ae0f-dcca-fd9b-1f09-bc0f0e092b63" at position 0
2023-01-24 00:59:56,214 - kedro.pipeline.node - ERROR - Node 'datetime_preprocessing_node: datetime_preprocessing([raw_data]) -> [preprocessed_raw_data]' failed with error: 
name 'parameters' is not defined
2023-01-24 01:07:37,749 - kedro.pipeline.node - ERROR - Node 'datetime_preprocessing_node: datetime_preprocessing([raw_data,params:model_options]) -> [preprocessed_raw_data]' failed with error: 
"['aitTemperature.avgOverTime'] not in index"
2023-01-24 01:08:28,470 - kedro.pipeline.node - ERROR - Node 'run_outlier_detection_node: run_outlier_detection([preprocessed_raw_data]) -> [processed_data]' failed with error: 
name 'np' is not defined
2023-01-25 12:20:27,261 - kedro.pipeline.node - ERROR - Node 'get_imputated_pollutant_data_node: get_imputated_pollutant_data([time_synchronized_data,params:imputer_options]) -> None' failed with error: 
'<' not supported between instances of 'str' and 'int'
2023-01-25 12:30:38,019 - kedro.pipeline.node - ERROR - Node 'get_imputated_pollutant_data_node: get_imputated_pollutant_data([time_synchronized_data,params:imputer_options]) -> None' failed with error: 
Shape of passed values is (76896, 2), indices imply (76896, 36)
2023-01-25 15:45:37,757 - kedro.pipeline.node - ERROR - Node 'get_imputated_pollutant_data_node: get_imputated_pollutant_data([time_synchronized_data,params:imputer_options]) -> None' failed with error: 
[Errno 2] No such file or directory: 'airQualityIndex_imputated_data.parquet'
2023-01-30 17:22:48,514 - kedro.pipeline.node - ERROR - Node 'datetime_preprocessing_node: datetime_preprocessing([raw_data]) -> [preprocessed_raw_data]' failed with error: 
name 'parameters' is not defined
2023-01-30 19:22:50,959 - kedro.pipeline.node - ERROR - Node 'get_location_data_node: get_location_data([sensor_data,sensor_ids,params:deep_learning_model]) -> [known_latlon,unknown_latlon,latlon]' failed with error: 
name 'ids' is not defined
2023-01-31 01:42:06,519 - kedro.pipeline.node - ERROR - Node 'deep_learning_model_node: deep_learning_model([known_latlon,unknown_latlon,params:deep_learning_model]) -> None' failed with error: 
Found array with 0 sample(s) (shape=(0, 76992)) while a minimum of 1 is required by StandardScaler.
2023-01-31 01:46:06,290 - kedro.pipeline.node - ERROR - Node 'deep_learning_model_node: deep_learning_model([known_latlon,unknown_latlon,params:deep_learning_model]) -> None' failed with error: 
Found array with 0 sample(s) (shape=(0, 76992)) while a minimum of 1 is required by StandardScaler.
2023-01-31 01:47:38,815 - kedro.pipeline.node - ERROR - Node 'deep_learning_model_node: deep_learning_model([known_latlon,unknown_latlon,params:deep_learning_model]) -> None' failed with error: 
Found array with 0 sample(s) (shape=(0, 76992)) while a minimum of 1 is required by StandardScaler.
2023-01-31 01:57:18,888 - kedro.pipeline.node - ERROR - Node 'deep_learning_model_node: deep_learning_model([known_latlon,unknown_latlon,params:deep_learning_model]) -> None' failed with error: 
Graph execution error:

Detected at node 'StatefulPartitionedCall' defined at (most recent call last):
    File "/Users/chetan/opt/anaconda3/envs/Kedro-Pune-AQM/bin/kedro", line 8, in <module>
      sys.exit(main())
    File "/Users/chetan/opt/anaconda3/envs/Kedro-Pune-AQM/lib/python3.10/site-packages/kedro/framework/cli/cli.py", line 211, in main
      cli_collection()
    File "/Users/chetan/opt/anaconda3/envs/Kedro-Pune-AQM/lib/python3.10/site-packages/click/core.py", line 1130, in __call__
      return self.main(*args, **kwargs)
    File "/Users/chetan/opt/anaconda3/envs/Kedro-Pune-AQM/lib/python3.10/site-packages/kedro/framework/cli/cli.py", line 139, in main
      super().main(
    File "/Users/chetan/opt/anaconda3/envs/Kedro-Pune-AQM/lib/python3.10/site-packages/click/core.py", line 1055, in main
      rv = self.invoke(ctx)
    File "/Users/chetan/opt/anaconda3/envs/Kedro-Pune-AQM/lib/python3.10/site-packages/click/core.py", line 1657, in invoke
      return _process_result(sub_ctx.command.invoke(sub_ctx))
    File "/Users/chetan/opt/anaconda3/envs/Kedro-Pune-AQM/lib/python3.10/site-packages/click/core.py", line 1404, in invoke
      return ctx.invoke(self.callback, **ctx.params)
    File "/Users/chetan/opt/anaconda3/envs/Kedro-Pune-AQM/lib/python3.10/site-packages/click/core.py", line 760, in invoke
      return __callback(*args, **kwargs)
    File "/Users/chetan/opt/anaconda3/envs/Kedro-Pune-AQM/lib/python3.10/site-packages/kedro/framework/cli/project.py", line 382, in run
      session.run(
    File "/Users/chetan/opt/anaconda3/envs/Kedro-Pune-AQM/lib/python3.10/site-packages/kedro/framework/session/session.py", line 404, in run
      run_result = runner.run(
    File "/Users/chetan/opt/anaconda3/envs/Kedro-Pune-AQM/lib/python3.10/site-packages/kedro/runner/runner.py", line 88, in run
      self._run(pipeline, catalog, hook_manager, session_id)
    File "/Users/chetan/opt/anaconda3/envs/Kedro-Pune-AQM/lib/python3.10/site-packages/kedro/runner/sequential_runner.py", line 70, in _run
      run_node(node, catalog, hook_manager, self._is_async, session_id)
    File "/Users/chetan/opt/anaconda3/envs/Kedro-Pune-AQM/lib/python3.10/site-packages/kedro/runner/runner.py", line 304, in run_node
      node = _run_node_sequential(node, catalog, hook_manager, session_id)
    File "/Users/chetan/opt/anaconda3/envs/Kedro-Pune-AQM/lib/python3.10/site-packages/kedro/runner/runner.py", line 398, in _run_node_sequential
      outputs = _call_node_run(
    File "/Users/chetan/opt/anaconda3/envs/Kedro-Pune-AQM/lib/python3.10/site-packages/kedro/runner/runner.py", line 356, in _call_node_run
      outputs = node.run(inputs)
    File "/Users/chetan/opt/anaconda3/envs/Kedro-Pune-AQM/lib/python3.10/site-packages/kedro/pipeline/node.py", line 344, in run
      outputs = self._run_with_list(inputs, self._inputs)
    File "/Users/chetan/opt/anaconda3/envs/Kedro-Pune-AQM/lib/python3.10/site-packages/kedro/pipeline/node.py", line 384, in _run_with_list
      return self._func(*(inputs[item] for item in node_inputs))
    File "/Users/chetan/opt/anaconda3/envs/Kedro-Pune-AQM/pune-air-quality/src/pune_air_quality/pipelines/deep_learning_interpolation/nodes.py", line 242, in deep_learning_model
      model.fit(known_latlon.to_numpy(), # input data
    File "/Users/chetan/opt/anaconda3/envs/Kedro-Pune-AQM/lib/python3.10/site-packages/keras/utils/traceback_utils.py", line 65, in error_handler
      return fn(*args, **kwargs)
    File "/Users/chetan/opt/anaconda3/envs/Kedro-Pune-AQM/lib/python3.10/site-packages/keras/engine/training.py", line 1650, in fit
      tmp_logs = self.train_function(iterator)
    File "/Users/chetan/opt/anaconda3/envs/Kedro-Pune-AQM/lib/python3.10/site-packages/keras/engine/training.py", line 1249, in train_function
      return step_function(self, iterator)
    File "/Users/chetan/opt/anaconda3/envs/Kedro-Pune-AQM/lib/python3.10/site-packages/keras/engine/training.py", line 1233, in step_function
      outputs = model.distribute_strategy.run(run_step, args=(data,))
    File "/Users/chetan/opt/anaconda3/envs/Kedro-Pune-AQM/lib/python3.10/site-packages/keras/engine/training.py", line 1222, in run_step
      outputs = model.train_step(data)
    File "/Users/chetan/opt/anaconda3/envs/Kedro-Pune-AQM/lib/python3.10/site-packages/keras/engine/training.py", line 1027, in train_step
      self.optimizer.minimize(loss, self.trainable_variables, tape=tape)
    File "/Users/chetan/opt/anaconda3/envs/Kedro-Pune-AQM/lib/python3.10/site-packages/keras/optimizers/optimizer_experimental/optimizer.py", line 527, in minimize
      self.apply_gradients(grads_and_vars)
    File "/Users/chetan/opt/anaconda3/envs/Kedro-Pune-AQM/lib/python3.10/site-packages/keras/optimizers/optimizer_experimental/optimizer.py", line 1140, in apply_gradients
      return super().apply_gradients(grads_and_vars, name=name)
    File "/Users/chetan/opt/anaconda3/envs/Kedro-Pune-AQM/lib/python3.10/site-packages/keras/optimizers/optimizer_experimental/optimizer.py", line 634, in apply_gradients
      iteration = self._internal_apply_gradients(grads_and_vars)
    File "/Users/chetan/opt/anaconda3/envs/Kedro-Pune-AQM/lib/python3.10/site-packages/keras/optimizers/optimizer_experimental/optimizer.py", line 1166, in _internal_apply_gradients
      return tf.__internal__.distribute.interim.maybe_merge_call(
    File "/Users/chetan/opt/anaconda3/envs/Kedro-Pune-AQM/lib/python3.10/site-packages/keras/optimizers/optimizer_experimental/optimizer.py", line 1216, in _distributed_apply_gradients_fn
      distribution.extended.update(
    File "/Users/chetan/opt/anaconda3/envs/Kedro-Pune-AQM/lib/python3.10/site-packages/keras/optimizers/optimizer_experimental/optimizer.py", line 1211, in apply_grad_to_update_var
      return self._update_step_xla(grad, var, id(self._var_key(var)))
Node: 'StatefulPartitionedCall'
could not find registered platform with id: 0x7fd3f91aa140
	 [[{{node StatefulPartitionedCall}}]] [Op:__inference_train_function_5556]
2023-01-31 02:06:15,169 - kedro.pipeline.node - ERROR - Node 'deep_learning_model_node: deep_learning_model([known_latlon,unknown_latlon,params:deep_learning_model]) -> None' failed with error: 
'inter_batch_size'
2023-01-31 02:07:24,493 - kedro.pipeline.node - ERROR - Node 'deep_learning_model_node: deep_learning_model([known_latlon,unknown_latlon,params:deep_learning_model]) -> None' failed with error: 
'numpy.ndarray' object has no attribute 'to_parquet'
2023-02-02 23:17:21,127 - kedro.pipeline.node - ERROR - Node 'aqi_deep_learning_model_node: deep_learning_model([airQualityIndex,known_latlon,unknown_latlon,params:deep_learning_model,params:airQualityIndex]) -> None' failed with error: 
'numpy.ndarray' object has no attribute 'to_csv'
2023-02-02 23:19:54,984 - kedro.pipeline.node - ERROR - Node 'aqi_deep_learning_model_node: deep_learning_model([airQualityIndex,known_latlon,unknown_latlon,params:deep_learning_model,params:airQualityIndex]) -> None' failed with error: 
'numpy.ndarray' object has no attribute 'to_csv'
2023-02-02 23:21:15,776 - kedro.pipeline.node - ERROR - Node 'aqi_deep_learning_model_node: deep_learning_model([airQualityIndex,known_latlon,unknown_latlon,params:deep_learning_model,params:airQualityIndex]) -> None' failed with error: 
'numpy.ndarray' object has no attribute 'to_csv'
2023-02-02 23:23:19,840 - kedro.pipeline.node - ERROR - Node 'aqi_deep_learning_model_node: deep_learning_model([airQualityIndex,known_latlon,unknown_latlon,params:deep_learning_model,params:airQualityIndex]) -> None' failed with error: 
'numpy.ndarray' object has no attribute 'to_csv'
2023-02-02 23:24:49,672 - kedro.pipeline.node - ERROR - Node 'aqi_deep_learning_model_node: deep_learning_model([airQualityIndex,known_latlon,unknown_latlon,params:deep_learning_model,params:airQualityIndex]) -> None' failed with error: 
'numpy.ndarray' object has no attribute 'to_csv'
